<?xml version="1.0" encoding="UTF-8"?>
<robot generator="Robot 7.0 (Python 3.12.3 on win32)" generated="2024-06-16T17:27:13.544510" rpa="false" schemaversion="5">
<suite id="s1" name="detalhesFilme" source="c:\Users\Usuario\Desktop\academy-qa-trabalho-final-grupo4-debugging-jedi\testesMobile\android\features\detalhesFilme.robot">
<test id="s1-t1" name="CT 01- usuário não logado deve conseguir acessar os detalhes dos filmes registrados no catálogo" line="9">
<kw name="Abrir App" owner="config" type="SETUP">
<kw name="Open Application" owner="AppiumLibrary">
<msg time="2024-06-16T17:27:16.761624" level="WARN">Retrying (Retry(total=2, connect=None, read=None, redirect=None, status=None)) after connection broken by 'NewConnectionError('&lt;urllib3.connection.HTTPConnection object at 0x000001C536661DF0&gt;: Failed to establish a new connection: [WinError 10061] Nenhuma conexão pôde ser feita porque a máquina de destino as recusou ativamente')': /session</msg>
<msg time="2024-06-16T17:27:18.811589" level="WARN">Retrying (Retry(total=1, connect=None, read=None, redirect=None, status=None)) after connection broken by 'NewConnectionError('&lt;urllib3.connection.HTTPConnection object at 0x000001C5352DC350&gt;: Failed to establish a new connection: [WinError 10061] Nenhuma conexão pôde ser feita porque a máquina de destino as recusou ativamente')': /session</msg>
<msg time="2024-06-16T17:27:20.861068" level="WARN">Retrying (Retry(total=0, connect=None, read=None, redirect=None, status=None)) after connection broken by 'NewConnectionError('&lt;urllib3.connection.HTTPConnection object at 0x000001C536633F20&gt;: Failed to establish a new connection: [WinError 10061] Nenhuma conexão pôde ser feita porque a máquina de destino as recusou ativamente')': /session</msg>
<kw name="Capture Page Screenshot" owner="AppiumLibrary">
<msg time="2024-06-16T17:27:22.895163" level="FAIL">No application is open</msg>
<doc>Takes a screenshot of the current page and embeds it into the log.</doc>
<status status="FAIL" start="2024-06-16T17:27:22.894161" elapsed="0.027427">No application is open</status>
</kw>
<msg time="2024-06-16T17:27:22.927523" level="WARN">Keyword 'Capture Page Screenshot' could not be run on failure: No application is open</msg>
<msg time="2024-06-16T17:27:22.931520" level="FAIL">MaxRetryError: HTTPConnectionPool(host='127.0.0.1', port=4723): Max retries exceeded with url: /session (Caused by NewConnectionError('&lt;urllib3.connection.HTTPConnection object at 0x000001C5366339B0&gt;: Failed to establish a new connection: [WinError 10061] Nenhuma conexão pôde ser feita porque a máquina de destino as recusou ativamente'))</msg>
<arg>http://127.0.0.1:4723</arg>
<arg>automationName=${ANDROID_AUTOMATION_NAME}</arg>
<arg>platformName=${ANDROID_PLATFORM_NAME}</arg>
<arg>platformVersion=${ANDROID_PLATFORM_VERSION}</arg>
<arg>appPackage=${APP_PACKAGE}</arg>
<arg>appActivity=${APP_ACTIVITY}</arg>
<arg>autoGrantPermissions=true</arg>
<doc>Opens a new application to given Appium server.
Capabilities of appium server, Android and iOS,
Please check https://github.com/appium/appium/blob/master/docs/en/writing-running-appium/server-args.md
| *Option*            | *Man.* | *Description*     |
| remote_url          | Yes    | Appium server url |
| alias               | no     | alias             |
| strict_ssl          | No     | allows you to send commands to an invalid certificate host like a self-signed one. |</doc>
<status status="FAIL" start="2024-06-16T17:27:14.494426" elapsed="8.442046">MaxRetryError: HTTPConnectionPool(host='127.0.0.1', port=4723): Max retries exceeded with url: /session (Caused by NewConnectionError('&lt;urllib3.connection.HTTPConnection object at 0x000001C5366339B0&gt;: Failed to establish a new connection: [WinError 10061] Nenhuma conexão pôde ser feita porque a máquina de destino as recusou ativamente'))</status>
</kw>
<status status="FAIL" start="2024-06-16T17:27:14.492423" elapsed="8.444049">MaxRetryError: HTTPConnectionPool(host='127.0.0.1', port=4723): Max retries exceeded with url: /session (Caused by NewConnectionError('&lt;urllib3.connection.HTTPConnection object at 0x000001C5366339B0&gt;: Failed to establish a new connection: [WinError 10061] Nenhuma conexão pôde ser feita porque a máquina de destino as recusou ativamente'))</status>
</kw>
<kw name="Teardown" owner="config" type="TEARDOWN">
<kw name="Run Keyword If Test Failed" owner="BuiltIn">
<kw name="Capture Page Screenshot" owner="AppiumLibrary">
<kw name="Capture Page Screenshot" owner="AppiumLibrary">
<msg time="2024-06-16T17:27:22.944472" level="FAIL">No application is open</msg>
<doc>Takes a screenshot of the current page and embeds it into the log.</doc>
<status status="FAIL" start="2024-06-16T17:27:22.944472" elapsed="0.007025">No application is open</status>
</kw>
<msg time="2024-06-16T17:27:22.961382" level="WARN">Keyword 'Capture Page Screenshot' could not be run on failure: No application is open</msg>
<msg time="2024-06-16T17:27:22.966390" level="FAIL">No application is open</msg>
<doc>Takes a screenshot of the current page and embeds it into the log.</doc>
<status status="FAIL" start="2024-06-16T17:27:22.944472" elapsed="0.021918">No application is open</status>
</kw>
<arg>Capture Page Screenshot</arg>
<doc>Runs the given keyword with the given arguments, if the test failed.</doc>
<status status="FAIL" start="2024-06-16T17:27:22.944472" elapsed="0.021918">No application is open</status>
</kw>
<kw name="Close All Applications" owner="AppiumLibrary">
<doc>Closes all open applications.</doc>
<status status="PASS" start="2024-06-16T17:27:22.966390" elapsed="0.015175"/>
</kw>
<status status="FAIL" start="2024-06-16T17:27:22.944472" elapsed="0.037093">No application is open</status>
</kw>
<status status="FAIL" start="2024-06-16T17:27:14.485514" elapsed="8.496051">Setup failed:
MaxRetryError: HTTPConnectionPool(host='127.0.0.1', port=4723): Max retries exceeded with url: /session (Caused by NewConnectionError('&lt;urllib3.connection.HTTPConnection object at 0x000001C5366339B0&gt;: Failed to establish a new connection: [WinError 10061] Nenhuma conexão pôde ser feita porque a máquina de destino as recusou ativamente'))

Also teardown failed:
No application is open</status>
</test>
<status status="FAIL" start="2024-06-16T17:27:13.559915" elapsed="9.421650"/>
</suite>
<statistics>
<total>
<stat pass="0" fail="1" skip="0">All Tests</stat>
</total>
<tag>
</tag>
<suite>
<stat pass="0" fail="1" skip="0" id="s1" name="detalhesFilme">detalhesFilme</stat>
</suite>
</statistics>
<errors>
<msg time="2024-06-16T17:27:14.231354" level="ERROR">Error in file 'c:\Users\Usuario\Desktop\academy-qa-trabalho-final-grupo4-debugging-jedi\testesMobile\android\base.robot' on line 4: Importing library 'FakerLibrary' failed: ModuleNotFoundError: No module named 'pkg_resources'
Traceback (most recent call last):
  File "C:\Users\Usuario\AppData\Local\Programs\Python\Python312\Lib\site-packages\FakerLibrary\__init__.py", line 1, in &lt;module&gt;
    import pkg_resources
PYTHONPATH:
  c:\Users\Usuario\.vscode\extensions\robocorp.robotframework-lsp-1.12.0\src\robotframework_debug_adapter
  C:\Users\Usuario\Desktop\academy-qa-trabalho-final-grupo4-debugging-jedi
  c:\Users\Usuario\.vscode\extensions\robocorp.robotframework-lsp-1.12.0\src
  c:\Users\Usuario\.vscode\extensions\robocorp.robotframework-lsp-1.12.0\src\robotframework_ls\vendored
  C:\Users\Usuario\AppData\Local\Programs\Python\Python312\python312.zip
  C:\Users\Usuario\AppData\Local\Programs\Python\Python312\DLLs
  C:\Users\Usuario\AppData\Local\Programs\Python\Python312\Lib
  C:\Users\Usuario\AppData\Local\Programs\Python\Python312
  C:\Users\Usuario\AppData\Local\Programs\Python\Python312\Lib\site-packages</msg>
<msg time="2024-06-16T17:27:14.248012" level="ERROR">Error in file 'c:\Users\Usuario\Desktop\academy-qa-trabalho-final-grupo4-debugging-jedi\testesMobile\android\base.robot' on line 5: Importing library 'RequestsLibrary' failed: ModuleNotFoundError: No module named 'RequestsLibrary'
Traceback (most recent call last):
  None
PYTHONPATH:
  c:\Users\Usuario\.vscode\extensions\robocorp.robotframework-lsp-1.12.0\src\robotframework_debug_adapter
  C:\Users\Usuario\Desktop\academy-qa-trabalho-final-grupo4-debugging-jedi
  c:\Users\Usuario\.vscode\extensions\robocorp.robotframework-lsp-1.12.0\src
  c:\Users\Usuario\.vscode\extensions\robocorp.robotframework-lsp-1.12.0\src\robotframework_ls\vendored
  C:\Users\Usuario\AppData\Local\Programs\Python\Python312\python312.zip
  C:\Users\Usuario\AppData\Local\Programs\Python\Python312\DLLs
  C:\Users\Usuario\AppData\Local\Programs\Python\Python312\Lib
  C:\Users\Usuario\AppData\Local\Programs\Python\Python312
  C:\Users\Usuario\AppData\Local\Programs\Python\Python312\Lib\site-packages</msg>
<msg time="2024-06-16T17:27:14.285063" level="ERROR">Error in file 'c:\Users\Usuario\Desktop\academy-qa-trabalho-final-grupo4-debugging-jedi\testesMobile\android\page\loginPage.robot' on line 3: Resource file '..\..\base.robot' does not exist.</msg>
<msg time="2024-06-16T17:27:14.300456" level="ERROR">Error in file 'c:\Users\Usuario\Desktop\academy-qa-trabalho-final-grupo4-debugging-jedi\testesMobile\android\page\loginPage.robot' on line 4: Importing library 'FakerLibrary' failed: ModuleNotFoundError: No module named 'pkg_resources'
Traceback (most recent call last):
  File "C:\Users\Usuario\AppData\Local\Programs\Python\Python312\Lib\site-packages\FakerLibrary\__init__.py", line 1, in &lt;module&gt;
    import pkg_resources
PYTHONPATH:
  c:\Users\Usuario\.vscode\extensions\robocorp.robotframework-lsp-1.12.0\src\robotframework_debug_adapter
  C:\Users\Usuario\Desktop\academy-qa-trabalho-final-grupo4-debugging-jedi
  c:\Users\Usuario\.vscode\extensions\robocorp.robotframework-lsp-1.12.0\src
  c:\Users\Usuario\.vscode\extensions\robocorp.robotframework-lsp-1.12.0\src\robotframework_ls\vendored
  C:\Users\Usuario\AppData\Local\Programs\Python\Python312\python312.zip
  C:\Users\Usuario\AppData\Local\Programs\Python\Python312\DLLs
  C:\Users\Usuario\AppData\Local\Programs\Python\Python312\Lib
  C:\Users\Usuario\AppData\Local\Programs\Python\Python312
  C:\Users\Usuario\AppData\Local\Programs\Python\Python312\Lib\site-packages</msg>
<msg time="2024-06-16T17:27:14.314586" level="ERROR">Error in file 'c:\Users\Usuario\Desktop\academy-qa-trabalho-final-grupo4-debugging-jedi\testesMobile\android\utils\commons.robot' on line 6: Importing library 'FakerLibrary' failed: ModuleNotFoundError: No module named 'pkg_resources'
Traceback (most recent call last):
  File "C:\Users\Usuario\AppData\Local\Programs\Python\Python312\Lib\site-packages\FakerLibrary\__init__.py", line 1, in &lt;module&gt;
    import pkg_resources
PYTHONPATH:
  c:\Users\Usuario\.vscode\extensions\robocorp.robotframework-lsp-1.12.0\src\robotframework_debug_adapter
  C:\Users\Usuario\Desktop\academy-qa-trabalho-final-grupo4-debugging-jedi
  c:\Users\Usuario\.vscode\extensions\robocorp.robotframework-lsp-1.12.0\src
  c:\Users\Usuario\.vscode\extensions\robocorp.robotframework-lsp-1.12.0\src\robotframework_ls\vendored
  C:\Users\Usuario\AppData\Local\Programs\Python\Python312\python312.zip
  C:\Users\Usuario\AppData\Local\Programs\Python\Python312\DLLs
  C:\Users\Usuario\AppData\Local\Programs\Python\Python312\Lib
  C:\Users\Usuario\AppData\Local\Programs\Python\Python312
  C:\Users\Usuario\AppData\Local\Programs\Python\Python312\Lib\site-packages</msg>
<msg time="2024-06-16T17:27:14.351154" level="ERROR">Error in file 'c:\Users\Usuario\Desktop\academy-qa-trabalho-final-grupo4-debugging-jedi\testesMobile\android\base.robot' on line 13: Resource file 'android\pages\registrarPage.robot' does not exist.</msg>
<msg time="2024-06-16T17:27:14.360812" level="ERROR">Error in file 'c:\Users\Usuario\Desktop\academy-qa-trabalho-final-grupo4-debugging-jedi\testesMobile\android\base.robot' on line 14: Resource file 'android\pages\loginTest.robot' does not exist.</msg>
<msg time="2024-06-16T17:27:14.444293" level="ERROR">Error in file 'c:\Users\Usuario\Desktop\academy-qa-trabalho-final-grupo4-debugging-jedi\testesMobile\android\page\Page.robot' on line 7: Importing library 'FakerLibrary' failed: ModuleNotFoundError: No module named 'pkg_resources'
Traceback (most recent call last):
  File "C:\Users\Usuario\AppData\Local\Programs\Python\Python312\Lib\site-packages\FakerLibrary\__init__.py", line 1, in &lt;module&gt;
    import pkg_resources
PYTHONPATH:
  c:\Users\Usuario\.vscode\extensions\robocorp.robotframework-lsp-1.12.0\src\robotframework_debug_adapter
  C:\Users\Usuario\Desktop\academy-qa-trabalho-final-grupo4-debugging-jedi
  c:\Users\Usuario\.vscode\extensions\robocorp.robotframework-lsp-1.12.0\src
  c:\Users\Usuario\.vscode\extensions\robocorp.robotframework-lsp-1.12.0\src\robotframework_ls\vendored
  C:\Users\Usuario\AppData\Local\Programs\Python\Python312\python312.zip
  C:\Users\Usuario\AppData\Local\Programs\Python\Python312\DLLs
  C:\Users\Usuario\AppData\Local\Programs\Python\Python312\Lib
  C:\Users\Usuario\AppData\Local\Programs\Python\Python312
  C:\Users\Usuario\AppData\Local\Programs\Python\Python312\Lib\site-packages</msg>
<msg time="2024-06-16T17:27:14.467566" level="ERROR">Error in file 'c:\Users\Usuario\Desktop\academy-qa-trabalho-final-grupo4-debugging-jedi\testesMobile\android\page\detalhesPage.robot' on line 7: Importing library 'RequestsLibrary' failed: ModuleNotFoundError: No module named 'RequestsLibrary'
Traceback (most recent call last):
  None
PYTHONPATH:
  c:\Users\Usuario\.vscode\extensions\robocorp.robotframework-lsp-1.12.0\src\robotframework_debug_adapter
  C:\Users\Usuario\Desktop\academy-qa-trabalho-final-grupo4-debugging-jedi
  c:\Users\Usuario\.vscode\extensions\robocorp.robotframework-lsp-1.12.0\src
  c:\Users\Usuario\.vscode\extensions\robocorp.robotframework-lsp-1.12.0\src\robotframework_ls\vendored
  C:\Users\Usuario\AppData\Local\Programs\Python\Python312\python312.zip
  C:\Users\Usuario\AppData\Local\Programs\Python\Python312\DLLs
  C:\Users\Usuario\AppData\Local\Programs\Python\Python312\Lib
  C:\Users\Usuario\AppData\Local\Programs\Python\Python312
  C:\Users\Usuario\AppData\Local\Programs\Python\Python312\Lib\site-packages</msg>
<msg time="2024-06-16T17:27:16.761624" level="WARN">Retrying (Retry(total=2, connect=None, read=None, redirect=None, status=None)) after connection broken by 'NewConnectionError('&lt;urllib3.connection.HTTPConnection object at 0x000001C536661DF0&gt;: Failed to establish a new connection: [WinError 10061] Nenhuma conexão pôde ser feita porque a máquina de destino as recusou ativamente')': /session</msg>
<msg time="2024-06-16T17:27:18.811589" level="WARN">Retrying (Retry(total=1, connect=None, read=None, redirect=None, status=None)) after connection broken by 'NewConnectionError('&lt;urllib3.connection.HTTPConnection object at 0x000001C5352DC350&gt;: Failed to establish a new connection: [WinError 10061] Nenhuma conexão pôde ser feita porque a máquina de destino as recusou ativamente')': /session</msg>
<msg time="2024-06-16T17:27:20.861068" level="WARN">Retrying (Retry(total=0, connect=None, read=None, redirect=None, status=None)) after connection broken by 'NewConnectionError('&lt;urllib3.connection.HTTPConnection object at 0x000001C536633F20&gt;: Failed to establish a new connection: [WinError 10061] Nenhuma conexão pôde ser feita porque a máquina de destino as recusou ativamente')': /session</msg>
<msg time="2024-06-16T17:27:22.927523" level="WARN">Keyword 'Capture Page Screenshot' could not be run on failure: No application is open</msg>
<msg time="2024-06-16T17:27:22.961382" level="WARN">Keyword 'Capture Page Screenshot' could not be run on failure: No application is open</msg>
</errors>
</robot>
